/*
 * Copyright 2018 the original author or authors.
 *
 * Licensed under the Apache License, Version 2.0 (the "License");
 * you may not use this file except in compliance with the License.
 * You may obtain a copy of the License at
 *
 *      http://www.apache.org/licenses/LICENSE-2.0
 *
 * Unless required by applicable law or agreed to in writing, software
 * distributed under the License is distributed on an "AS IS" BASIS,
 * WITHOUT WARRANTIES OR CONDITIONS OF ANY KIND, either express or implied.
 * See the License for the specific language governing permissions and
 * limitations under the License.
 */

package org.gradle.kotlin.dsl.concurrent

import org.gradle.kotlin.dsl.support.useToRun

import org.hamcrest.CoreMatchers.equalTo
import org.hamcrest.CoreMatchers.sameInstance
import org.hamcrest.MatcherAssert.assertThat

import org.junit.Test

import java.io.IOException

import java.util.concurrent.CompletableFuture
import java.util.concurrent.CountDownLatch
import java.util.concurrent.Executors
import java.util.concurrent.TimeUnit


class DefaultAsyncIOScopeFactoryTest {

    @Test
    fun `#io failure is reported upon IOScope#close`() {

        withAsyncIOScopeFactory {

            val failure = IOException()

            val scope = newScope().apply {
                io { throw failure }
            }

            assertThat(
                runCatching { scope.close() }.exceptionOrNull(),
                sameInstance<Throwable>(failure)
            )
        }
    }

    @Test
    fun `#io failure is reported upon next #io call`() {

        withAsyncIOScopeFactory {

            val expectedFailure = IOException()

            val failureLatch = FailureLatch()
            val scope = newScope().apply {
                io { failureLatch.failWith(expectedFailure) }
            }
            failureLatch.await()

            assertThat(
                runCatching { scope.io { } }.exceptionOrNull(),
                sameInstance<Throwable>(expectedFailure)
            )
        }
    }

    @Test
    fun `IOScope failures are isolated`() {

        withAsyncIOScopeFactory {

            // given: a failure in one scope
            val failureLatch = FailureLatch()
            newScope().apply {
                io { failureLatch.failWith(IllegalStateException()) }
            }
            failureLatch.await()

            // then: actions can still be scheduled in separate scope
            val isolatedScopeAction = CompletableFuture<Unit>()
            newScope().apply {
                io { isolatedScopeAction.complete(Unit) }
            }
            assertThat(
                isolatedScopeAction.get(50, TimeUnit.MILLISECONDS),
                equalTo(Unit)
            )
        }
    }

    private
    class FailureLatch {

        private
        val latch: CountDownLatch = CountDownLatch(1)

        fun failWith(failure: Throwable) {
            latch.countDown()
            throw failure
        }

        fun await() {
            // There's small chance this thread can be awakened before
            // the exception in the IO thread is caught, so let's sleep a little
            latch.await(1, TimeUnit.SECONDS)
            Thread.sleep(1)
        }
    }

    private
    fun withAsyncIOScopeFactory(action: DefaultAsyncIOScopeFactory.() -> Unit) {
        DefaultAsyncIOScopeFactory { Executors.newSingleThreadExecutor() }.useToRun(action)
    }
}
